Workbook

Sheet Resultados da organização
A1: P.BORGES
B3: FINANCEIRO | M3: PACE | P3: OPERAÇÕES
E4: P.Borges | F4: Região | G4: PBvsRegião | H4: Tipologia | I4: PBvsTipo | J4: Nacional | K4: PBvsNac | M4: 20 | N4: 32 | S4: P.Borges | U4: Nacional/Objetivo | W4: Variação | X4: LY | Y4: YTD vs LY
B5: Crescimento de vendas | E5: 0.1184 | F5: 0.0635 | G5: =(E5-F5)*100 -> 5.49 | H5: 0.0475 | I5: =(E5-H5)*100 -> 7.09 | J5: 0.073 | K5: =(E5-J5)*100 -> 4.54 | P5: Tempos de Serviço | S5: 105 | U5: 95 | W5: =S5-U5 -> 10 | X5: 110 | Y5: =S5-X5 -> -5
B6: Crescimento de GC's | E6: 0.0411 | F6: 0.0231 | G6: =(E6-F6)*100 -> 1.8 | H6: 0.0053 | I6: =(E6-H6)*100 -> 3.58 | J6: 0.0263 | K6: =(E6-J6)*100 -> 1.48 | M6: 0.88 | N6: 0.94 | P6: Tempos Delivery | S6: =6.1*60 -> 366 | U6: =5.1*60 -> 306 | W6: =S6-U6 -> 60 | X6: =6.8*60 -> 408 | Y6: =S6-X6 -> -42
B7: Crescimento Delivery | E7: 0.1926 | F7: 0.1152 | G7: =(E7-F7)*100 -> 7.74 | H7: 0.0483 | I7: =(E7-H7)*100 -> 14.43 | J7: 0.1623 | K7: =(E7-J7)*100 -> 3.03 | P7: Fastinsight | S7: 0.974 | U7: 0.941 | W7: =(S7-U7)*100 -> 3.3 | X7: 0.951 | Y7: =(S7-X7)*100 -> 2.3
B8: Crescimento GC's Delivery | E8: 0.1055 | F8: 0.091 | G8: =(E8-F8)*100 -> 1.45 | H8: 0.0318 | I8: =(E8-H8)*100 -> 7.37 | J8: 0.1095 | K8: =(E8-J8)*100 -> -0.4 | P8: Turnover | U8: 0.6 | W8: =S8-U8 -> -0.6
B9: Peso Delivery | E9: 0.525 | F9: 0.289 | G9: =(E9-F9)*100 -> 23.6 | H9: 0.279 | I9: =(E9-H9)*100 -> 24.6 | J9: 0.181 | K9: =(E9-J9)*100 -> 34.4 | P9: Staffing | U9: 0.35 | W9: =S9-U9 -> -0.35
B10: Peso MOP | E10: 0.0036 | F10: 0.0072 | G10: =(E10-F10)*100 -> -0.36 | H10: 0.007 | I10: =(E10-H10)*100 -> -0.34 | J10: 0.0093 | K10: =(E10-J10)*100 -> -0.57 | P10: BSV | U10: 1 | W10: =S10-U10 -> -1
M11: Vendas YTD
B12: *Atualizado 1-8 | L12: 2024 | M12: 2525592 | N12: Variação
L13: 2025 | M13: 2824671 | N13: =M13-M12 -> 299079 | O13: =N13/M12 -> 0.11841936
F15: Janeiro | G15: Fevereiro | H15: Março | I15: Abril | J15: Maio | K15: Junho | L15: Julho | M15: Agosto | N15: Setembro | O15: Outubro | P15: Novembro | Q15: Dezembro | R15: YTD | S15: LY | T15: Variação
C16: Crescimento de vendas | R16: =E5 -> 0.1184 | T16: =R16-S16 -> 0.1184
C17: Crescimento de GC's | R17: =E6 -> 0.0411 | T17: =R17-S17 -> 0.0411
C18: Crescimento Delivery | R18: =E7 -> 0.1926 | T18: =R18-S18 -> 0.1926
C19: Crescimento GC's Delivery | R19: =E8 -> 0.1055 | T19: =R19-S19 -> 0.1055
C20: Peso Delivery | F20: =(Serviço!C71+Serviço!C82)/(Serviço!C81+Serviço!C70) -> 0.57534934 | G20: =(Serviço!D71+Serviço!D82)/(Serviço!D81+Serviço!D70) -> 0.48743466 | H20: =(Serviço!E71+Serviço!E82)/(Serviço!E81+Serviço!E70) -> 0.55094074 | I20: =(Serviço!F71+Serviço!F82)/(Serviço!F81+Serviço!F70) -> 0.48917944 | J20: =(Serviço!G71+Serviço!G82)/(Serviço!G81+Serviço!G70) -> 0.51277637 | K20: =(Serviço!H71+Serviço!H82)/(Serviço!H81+Serviço!H70) -> 0.51137935 | L20: =(Serviço!I71+Serviço!I82)/(Serviço!I81+Serviço!I70) -> 0.47767429 | M20: =(Serviço!J71+Serviço!J82)/(Serviço!J81+Serviço!J70) -> 0.45997226 | ... R20: =(Serviço!O71+Serviço!O82)/(Serviço!O81+Serviço!O70) -> 0.51384802 | T20: =R20-S20 -> 0.51384802
C21: Peso MOP | F21: 0.0039 | G21: 0.0033 | H21: 0.0034 | I21: 0.0038 | J21: 0.0038 | K21: =(Serviço!H88+Serviço!H77)/(Serviço!H70+Serviço!H81) -> 0.0039636347 | L21: =(Serviço!I88+Serviço!I77)/(Serviço!I70+Serviço!I81) -> 0.0040832965 | M21: =(Serviço!J88+Serviço!J77)/(Serviço!J70+Serviço!J81) -> 0.003587231 | N21: =(Serviço!K88+Serviço!K77)/(Serviço!K70+Serviço!K81) -> 0.0041365766 | O21: =(Serviço!L88+Serviço!L77)/(Serviço!L70+Serviço!L81) -> 0.0034680251 | P21: =(Serviço!M88+Serviço!M77)/(Serviço!M70+Serviço!M81) -> 0.0030682228 | Q21: =(Serviço!N88+Serviço!N77)/(Serviço!N70+Serviço!N81) -> 0.0044746874 | R21: =(Serviço!O88+Serviço!O77)/(Serviço!O70+Serviço!O81) -> 0.0038939401
C22: Tempos de Serviço | F22: =Serviço!O9 -> 110 | G22: =Serviço!P9 -> 110 | H22: =Serviço!Q9 -> 114 | I22: =Serviço!R9 -> 117 | J22: =Serviço!S9 -> 119 | K22: =Serviço!T9 -> 123 | L22: =Serviço!U9 -> 145 | M22: =Serviço!V9 -> 143 | ... R22: =Serviço!AA9 -> 111 | S22: 128 | T22: =R22-S22 -> -17
C23: Tempos de serviço Nacional | F23: 130 | G23: 136 | H23: 150 | I23: 156 | J23: 162 | T23: =R23-S23 -> 0
C24: Fastinsight | F24: 0.981 | G24: 0.98 | H24: 0.963 | I24: 0.974 | J24: 0.969 | T24: =R24-S24 -> 0
C25: Fastinsight Nacional | F25: 0.952 | G25: 0.947 | H25: 0.937 | I25: 0.935 | J25: 0.927 | T25: =R25-S25 -> 0
C26: Turnover | T26: =R26-S26 -> 0
C27: Staffing | T27: =R27-S27 -> 0
T28: =R28-S28 -> 0
F30: Janeiro | G30: Fevereiro | H30: Março | I30: Abril | J30: Maio | K30: Junho | L30: Julho | M30: Agosto | N30: Setembro | O30: Outubro | P30: Novembro | Q30: Dezembro | R30: YTD | S30: LY | T30: Variação
C31: Vendas PB | S31: 0.1669 | T31: =(R31-S31)*100 -> -16.69
C32: Vendas Região | S32: 0.1952 | T32: =(R32-S32)*100 -> -19.52
C33: PB vs Região | F33: =F31-F32 -> 0 | G33: =G31-G32 -> 0 | H33: =H31-H32 -> 0 | I33: =I31-I32 -> 0 | J33: =J31-J32 -> 0 | K33: =K31-K32 -> 0 | L33: =L31-L32 -> 0 | M33: =M31-M32 -> 0 | ... R33: =R31-R32 -> 0 | T33: =(R33-S33)*100 -> 0
C34: Vendas Tipologia (Free Stand) | S34: 0.1538 | T34: =(R34-S34)*100 -> -15.38
C35: PB vs Tipologia | F35: =F31-F34 -> 0 | G35: =G31-G34 -> 0 | H35: =H31-H34 -> 0 | I35: =I31-I34 -> 0 | J35: =J31-J34 -> 0 | K35: =K31-K34 -> 0 | L35: =L31-L34 -> 0 | M35: =M31-M34 -> 0 | ... R35: =R31-R34 -> 0 | T35: =(R35-S35)*100 -> 0
C36: Vendas Nacional | R36: 0.0852 | S36: 0.1952 | T36: =(R36-S36)*100 -> -11
C37: PB vs Nacional | F37: =F31-F36 -> 0 | G37: =G31-G36 -> 0 | H37: =H31-H36 -> 0 | I37: =I31-I36 -> 0 | J37: =J31-J36 -> 0 | K37: =K31-K36 -> 0 | L37: =L31-L36 -> 0 | M37: =M31-M36 -> 0 | ... R37: =R31-R36 -> -0.0852 | T37: =(R37-S37)*100 -> -8.52
C38: GC's PB | S38: 0.1074 | T38: =(R38-S38)*100 -> -10.74
C39: Gc's Região | S39: 0.1444 | T39: =(R39-S39)*100 -> -14.44
C40: Gc's Tipologia | S40: 0.0906 | T40: =(R40-S40)*100 -> -9.06
C41: Gc's Nacional | S41: 0.1444 | T41: =(R41-S41)*100 -> -14.44
C42: Delivery PB | F42: =F18 -> 0 | G42: =G18 -> 0 | H42: =H18 -> 0 | I42: =I18 -> 0 | J42: =J18 -> 0 | K42: =K18 -> 0 | L42: =L18 -> 0 | M42: =M18 -> 0 | ... R42: =R18 -> 0.1926 | S42: 0.1274 | T42: =(R42-S42)*100 -> 6.52
C43: Delivery Região | S43: 0.0976 | T43: =(R43-S43)*100 -> -9.76
...

Sheet Serviço
B2: TEMPOS DE SERVIÇO
B4: YTD | H4: DEZEMBRO
B5: AMADORA | C5: TEMPO | D5: VAR | E5: RANK | F5: Percentil | G5: OBJETIVO | H5: AMADORA | I5: TEMPO | J5: VAR | K5: RANK | L5: Percentil
B6: ALMOÇO | G6: 110 | H6: ALMOÇO | O6: Jan | P6: fev | Q6: mar | R6: Abr | S6: Mai | T6: Jun | U6: Jul | V6: Ago | W6: Set | X6: Out | Y6: Nov | Z6: Dez | AA6: YTD | AB6: LY
B7: JANTAR | H7: JANTAR | M7: R2P | N7: AMADORA | O7: 116 | P7: 115 | Q7: 122 | R7: 128 | S7: 132 | T7: 134 | U7: 151 | V7: 158 | W7: 133 | X7: 152 | Y7: 128 | AA7: 116 | AB7: 118
B8: DIA | C8: 133 | D8: -1 | E8: 17 | F8: =(E8/215) -> 0.079069767 | H8: DIA | I8: 123 | K8: 23 | L8: =(K8/215) -> 0.10697674 | N8: QUELUZ | O8: 100 | P8: 102 | Q8: 101 | R8: 101 | S8: 101 | T8: 107 | U8: 135 | V8: 113 | W8: 99 | X8: 104 | Y8: 122 | AA8: 103 | AB8: 100
B9: YTD | H9: DEZEMBRO | N9: P.BORGES | O9: 110 | P9: 110 | Q9: 114 | R9: 117 | S9: 119 | T9: 123 | U9: 145 | V9: 143 | W9: 125 | X9: 131 | Y9: 126 | AA9: 111 | AB9: 110
B10: QUELUZ | C10: TEMPO | D10: VAR | E10: RANK | F10: Percentil | G10: OBJETIVO | H10: QUELUZ | I10: TEMPO | J10: VAR | K10: RANK | L10: Percentil | M10: Delivery | N10: AMADORA | O10: 19.6 | P10: 19.3 | Q10: 19.7 | R10: 18.4 | S10: 16.7 | T10: 18.5 | U10: 18.6 | V10: 18.2 | W10: 17.7 | X10: 19.3
B11: ALMOÇO | G11: 110 | H11: ALMOÇO | N11: QUELUZ | O11: 18.6 | P11: 18.8 | Q11: 19.7 | R11: 18.8 | S11: 17.6 | T11: 19.2 | U11: 21.2 | V11: 18.9 | W11: 17.8 | X11: 19.3
B12: JANTAR | H12: JANTAR | N12: P.BORGES | O12: 19.1 | P12: 19.1 | Q12: 19.7 | R12: 18.5 | S12: 17.1 | T12: 18.2 | U12: 19.6 | V12: 18.5 | W12: 17.7 | X12: 19.3
B13: DIA | C13: 107 | D13: 1 | E13: 3 | F13: =(E13/215) -> 0.013953488 | H13: DIA | I13: 106 | K13: 9 | L13: =(K13/215) -> 0.041860465
B14: DELIVERY | H14: DELIVERY
B15: DELIVERY | C15: TEMPO | D15: VAR | E15: RANK | F15: Percentil | G15: NACIONAL | H15: DELIVERY | I15: TEMPO | J15: VAR | K15: RANK | L15: Percentil
B16: AMADORA | C16: 81 | D16: -1 | E16: 53 | F16: =(E16/215) -> 0.24651163 | G16: 170 | H16: AMADORA | I16: 65 | K16: 14 | L16: =(K16/215) -> 0.065116279
B17: QUELUZ | C17: 74 | D17: 2 | E17: 29 | F17: =(E17/215) -> 0.13488372 | H17: QUELUZ | I17: 79 | K17: 52 | L17: =(K17/215) -> 0.24186047
B19: QUALIDADE DO SERVIÇO
C21: FASTINSIGHT AMADORA | K21: FASTINSIGHT QUELUZ
C22: DEZEMBRO | G22: ANO | K22: DEZEMBRO | O22: ANO
C23: SG | D23: LIMPEZA | E23: SIMPATIA | F23: RAPIDEZ | G23: SG | I23: NPS | K23: SG | L23: LIMPEZA | M23: QUALIDADE | N23: RAPIDEZ | O23: SG | Q23: NPS
C24: 96.55 | D24: 97.78 | E24: 93.33 | F24: 93.33 | G24: 95.87 | I24: 96.79 | K24: 98.51 | L24: 100 | M24: 100 | N24: 100
C26: SG | D26: Jan | E26: Fev | F26: Mar | G26: Abr | H26: Mai | I26: Jun | J26: Jul | K26: Ago | L26: Set | M26: Out | N26: Nov | O26: Dez | P26: YTD | Q26: LY | R26: OBJETIVO | S26: NACIONAL
C27: Amadora | D27: 94.96 | E27: 96.5 | F27: 95.74 | G27: 97.03 | H27: 96.13 | I27: 95.16 | J27: 95.87 | K27: 96.43 | L27: 95.47 | M27: 96.4 | N27: 95.39 | O27: 93.3 | P27: 95.34 | Q27: 94.76 | R27: 95 | S27: 90.65
C28: Queluz | D28: 96.86 | E28: 97.68 | F28: 96.41 | G28: 96.66 | H28: 97.46 | I28: 98.35 | J28: 97.19 | K28: 97.45 | L28: 98.28 | M28: 96.63 | N28: 96.63 | O28: 100 | P28: 97.24 | Q28: 95.6 | R28: 95
C30: RÁCIO DE RECLAMAÇÕES
C31: GC's Amadora | E31: 275602 | F31: Amadora | G31: SALA | H31: DELIVERY | I31: TOTAL | J31: Queluz | K31: SALA | L31: DELIVERY | M31: TOTAL | N31: LY | O31: AMADORA | P31: QUELUZ | Q31: PBORGES
C32: GC's Queluz | E32: 173866 | F32: QUALIDADE | I32: =SUM(G32:H32) -> 0 | J32: QUALIDADE | M32: =SUM(K32:L32) -> 0 | N32: SALA | O32: 2 | P32: 3 | Q32: =O32+P32 -> 5
C33: P.Borges | E33: =((SUM(I32:I34)+SUM(M32:M34))/(E31+E32))*100000 -> 0.22248525 | F33: SERVIÇO | I33: =SUM(G33:H33) -> 0 | J33: SERVIÇO | L33: 1 | M33: =SUM(K33:L33) -> 1 | N33: DELIVERY | O33: 2 | P33: 6 | Q33: =O33+P33 -> 8
F34: LIMPEZA | I34: =SUM(G34:H34) -> 0 | J34: LIMPEZA | M34: =SUM(K34:L34) -> 0 | N34: GC'S | O34: 298405 | P34: 191877 | Q34: =O34+P34 -> 490282
F35: RÁCIO | G35: =(SUM(G32:G34)/E31)*100000 -> 0 | H35: =(SUM(H32:H34)/E31)*100000 -> 0 | I35: =(SUM(I32:I34)/E31)*100000 -> 0 | J35: RÁCIO | K35: =(SUM(K32:K34)/E32)*100000 -> 0 | L35: =(SUM(L32:L34)/E32)*100000 -> 0.57515558 | M35: =(SUM(M32:M34)/E32)*100000 -> 0.57515558 | N35: RÁCIO | O35: 1.34 | P35: 4.69 | Q35: 2.65
D37: Reclamações | E37: Jan | F37: Fev | G37: Mar | H37: Abr | I37: Mai | J37: Jun | K37: Jul | L37: Ago | M37: Set | N37: Out | O37: Nov | P37: Dez | Q37: OBJETIVO | S37: NACIONAL
D38: Amadora | E38: 0 | F38: 0 | G38: 0 | H38: 0 | I38: 0 | J38: 0 | K38: 0 | L38: 0 | M38: 0 | Q38: 2 | R38: 4 | S38: LR 1,26
D39: Queluz | E39: 0 | F39: 0 | G39: 0 | H39: 0 | I39: 0 | J39: 1 | K39: 0 | L39: 0 | M39: 0 | Q39: 2 | R39: 3 | S39: CC 0,91
E42: COMUNICAÇÃO DIGITAL
E43: Amadora | F43: VAR | G43: Ava. Total | H43: Ava. Mês | I43: Queluz | J43: Queluz | K43: VAR | L43: Ava. Total | M43: Ava. Mês | N43: LY | O43: Amadora | P43: QUELUZ
E44: 4.2 | F44: 0 | G44: 3459 | H44: 105 | J44: 4.3 | K44: 0 | L44: 3094 | M44: 33 | O44: 4.1 | P44: 4.2
E45: 4.2 | G45: 4004 | H45: 39 | J45: 4.3 | L45: 3605 | M45: 35 | O45: 4.2 | P45: 4.3
D46: UBER | E46: 4.2 | J46: 4.3 | N46: UBER | O46: 4.5 | P46: 4.5
D48: Google | E48: Jan | F48: Fev | G48: Mar | H48: Abr | I48: Mai | J48: Jun | K48: Jul | L48: Ago | M48: Set | N48: Out | O48: Nov | P48: Dez | Q48: OBJETIVO
D49: Amadora | E49: 4.2 | F49: 4.2 | G49: 4.2 | H49: 4.2 | I49: 4.3 | J49: 4.2 | K49: 4.2 | L49: 4.2 | M49: 4.2 | N49: 4.2 | Q49: 4.2
D50: Queluz | E50: 4.3 | F50: 4.3 | G50: 4.3 | H50: 4.3 | I50: 4.3 | J50: 4.3 | K50: 4.3 | L50: 4.3 | M50: 4.3 | N50: 4.3 | Q50: 4.3
...

Sheet Serviço MTD
B2: TEMPOS DE SERVIÇO
B4: YTD | H4: JUNHO
B5: AMADORA | C5: TEMPO | D5: VAR | E5: RANK | F5: Percentil | G5: OBJETIVO | H5: AMADORA | I5: TEMPO | J5: VAR | K5: RANK | L5: Percentil
B6: ALMOÇO | G6: 100 | H6: ALMOÇO | N6: Jan | O6: fev | P6: mar | Q6: Abr | R6: Mai | S6: Jun | T6: Jul | U6: Ago | V6: Set | W6: Out | X6: Nov | Y6: Dez | Z6: YTD | AA6: LY
B7: JANTAR | H7: JANTAR | M7: AMADORA | N7: 105 | O7: 101 | P7: 103 | Q7: 113 | AA7: 141
B8: DIA | C8: 107 | D8: 1 | E8: 14 | F8: =(E8/188) -> 0.074468085 | H8: DIA | I8: 176 | K8: 128 | L8: =(K8/188) -> 0.68085106 | M8: QUELUZ | N8: 88 | O8: 92 | P8: 94 | Q8: 107 | AA8: 107
B9: YTD | H9: MAIO | M9: P.BORGES | N9: 98 | O9: 97 | P9: 99 | Q9: 111 | AA9: 128
B10: QUELUZ | C10: TEMPO | D10: VAR | E10: RANK | F10: Percentil | G10: OBJETIVO | H10: QUELUZ | I10: TEMPO | J10: VAR | K10: RANK | L10: Percentil
B11: ALMOÇO | G11: 95 | H11: ALMOÇO
B12: JANTAR | H12: JANTAR
B13: DIA | C13: 97 | D13: 2 | E13: 4 | F13: =(E13/188) -> 0.021276596 | H13: DIA | I13: 126 | K13: 40 | L13: =(K13/188) -> 0.21276596
B15: QUALIDADE DO SERVIÇO
C17: FASTINSIGHT AMADORA | K17: FASTINSIGHT QUELUZ
C18: JUNHO | G18: ANO | K18: JUNHO | O18: ANO
C19: SG | D19: VAR | E19: NPS | F19: VAR | G19: SG | I19: NPS | K19: SG | L19: VAR | M19: NPS | N19: VAR | O19: SG | Q19: NPS
C20: 100 | E20: 100 | G20: 93.51 | I20: 95.31 | K20: 77.78 | M20: 81.48 | O20: 94.1 | Q20: 95.1
C22: SG | D22: Jan | E22: Fev | F22: Mar | G22: Abr | H22: Mai | I22: Jun | J22: Jul | K22: Ago | L22: Set | M22: Out | N22: Nov | O22: Dez | P22: YTD | Q22: LY | R22: OBJETIVO
C23: Amadora | D23: 91.46 | E23: 95.35 | F23: 93.24 | G23: 96.28 | H23: 93.8 | P23: 94.69 | Q23: 93.74 | R23: 93
C24: Queluz | D24: 94.09 | E24: 93.02 | F24: 93.87 | G24: 93.08 | H24: 94.07 | P24: 93.57 | Q24: 93.64 | R24: 93
C26: RÁCIO DE RECLAMAÇÕES
C27: GC's Amadora | E27: 106752 | F27: Amadora | G27: SALA | H27: DELIVERY | I27: TOTAL | J27: Queluz | K27: SALA | L27: DELIVERY | M27: TOTAL | N27: LY | O27: AMADORA | P27: QUELUZ | Q27: PBORGES
C28: GC's Queluz | E28: 71929 | F28: QUALIDADE | I28: =SUM(G28:H28) -> 0 | J28: QUALIDADE | K28: 1 | L28: 1 | M28: =SUM(K28:L28) -> 2 | N28: SALA | O28: 3 | P28: 0 | Q28: 3
C29: P.Borges | E29: =((SUM(I28:I30)+SUM(M28:M30))/(E27+E28))*100000 -> 1.1193132 | F29: SERVIÇO | I29: =SUM(G29:H29) -> 0 | J29: SERVIÇO | M29: =SUM(K29:L29) -> 0 | N29: DELIVERY | O29: 3 | P29: 3 | Q29: 6
F30: LIMPEZA | I30: =SUM(G30:H30) -> 0 | J30: LIMPEZA | M30: =SUM(K30:L30) -> 0 | N30: GC'S | O30: 266146 | P30: 176576 | Q30: 442722
F31: RÁCIO | G31: =(SUM(G28:G30)/E27)*100000 -> 0 | H31: =(SUM(H28:H30)/E27)*100000 -> 0 | I31: =(SUM(I28:I30)/E27)*100000 -> 0 | J31: RÁCIO | K31: =(SUM(K28:K30)/E28)*100000 -> 1.3902598 | L31: =(SUM(L28:L30)/E28)*100000 -> 1.3902598 | M31: =(SUM(M28:M30)/E28)*100000 -> 2.7805197 | N31: RÁCIO | O31: 2.25 | P31: 1.7 | Q31: 2.03
D33: Reclamações | E33: Jan | F33: Fev | G33: Mar | H33: Abr | I33: Mai | J33: Jun | K33: Jul | L33: Ago | M33: Set | N33: Out | O33: Nov | P33: Dez | Q33: OBJETIVO
D34: Amadora | E34: 0 | F34: 0 | G34: 0 | H34: 0 | Q34: 1.37 | R34: 4
D35: Queluz | E35: 6.32 | F35: 3.72 | G35: 4.27 | H35: 3.25 | Q35: 1.07 | R35: 2
E38: COMUNICAÇÃO DIGITAL
E39: Amadora | F39: VAR | G39: Ava. Total | H39: Ava. Mês | I39: Queluz | J39: Queluz | K39: VAR | L39: Ava. Total | M39: Ava. Mês | N39: LY | O39: Amadora | P39: QUELUZ
E40: 4 | G40: 1740 | H40: 4 | J40: 4 | K40: 0.1 | L40: 1921 | M40: 16 | O40: 4 | P40: 3.9
O41: 3.1 | P41: 0
D42: UBER | E42: 4.6 | G42: 2850 | H42: 633 | J42: 4.5 | L42: 1749 | M42: 379 | N42: UBER | O42: 4.4 | P42: 4.5
D44: Google | E44: Jan | F44: Fev | G44: Mar | H44: Abr | I44: Mai | J44: Jun | K44: Jul | L44: Ago | M44: Set | N44: Out | O44: Nov | P44: Dez | Q44: OBJETIVO
D45: Amadora | E45: 4 | F45: 4 | G45: 4 | H45: 4 | Q45: 4.1
D46: Queluz | E46: 3.9 | F46: 3.9 | G46: 4 | H46: 4 | Q46: 4.1
D48: UBER | E48: Jan | F48: Fev | G48: Mar | H48: Abr | I48: Mai | J48: Jun | K48: Jul | L48: Ago | M48: Set | N48: Out | O48: Nov | P48: Dez | Q48: OBJETIVO
D49: Amadora | E49: 4.5 | F49: 4.6 | G49: 4.6 | H49: 4.6 | P49: 4.6 | Q49: 4.5
D50: Queluz | E50: 4.5 | F50: 4.5 | G50: 4.5 | H50: 4.6 | Q50: 4.5
B52: 20/32 | C52: Jan | D52: Fev | E52: Mar | F52: Abr | G52: Mai | H52: Jun | I52: Jul | J52: Ago | K52: Set | L52: Out | M52: Nov | N52: Dez | O52: YTD | P52: OBJETIVO
...

Sheet Pessoas
B2: M.O. MENSAL
B4: VALOR DA HORA 2022 | E4: JANEIRO | F4: FEVEREIRO | G4: MARÇO | H4: ABRIL | I4: MAIO | J4: JUNHO | K4: JULHO | L4: AGOSTO | M4: SETEMBRO | N4: OUTUBRO | O4: NOVEMBRO | P4: DEZEMBRO | Q4: ANO
B5: 7.65 | D5: 20- VENDAS | E5: =C34 -> 288945 | F5: =C35 -> 254163 | G5: =C38 -> 280532 | H5: =C41 -> 247258 | I5: =C44 -> 251597 | J5: =C47 -> 252397 | K5: =C50 -> 268928 | L5: =C53 -> 286413 | M5: =C56 -> 246748 | N5: =C59 -> 236241 | O5: =C62 -> 236196 | P5: =C65 -> 82979 | Q5: =C68 -> 2932397 | S5: OBJETIVO
D6: 32- VENDAS | E6: =N34 -> 157396 | F6: =N35 -> 143160 | G6: =N38 -> 153168 | H6: =N41 -> 142879 | I6: =N44 -> 161979 | J6: =N47 -> 159094 | K6: =N50 -> 165280 | L6: =N53 -> 168534 | M6: =N56 -> 155517 | N6: =N59 -> 161680 | O6: =N62 -> 162732 | P6: =N65 -> 57366 | Q6: =N68 -> 1788785 | S6: 0.1
D7: 20- HORAS | E7: =D34 -> 3848 | F7: =D35 -> 3436 | G7: =D38 -> 3871 | H7: =D41 -> 3722 | I7: =D44 -> 3362 | J7: =+D47 -> 0 | K7: =+D50 -> 0 | L7: =+D53 -> 0 | M7: =+D56 -> 0 | N7: =+D59 -> 0 | O7: =+D62 -> 0 | P7: =+D65 -> 0 | Q7: =+D68 -> 18239 | S7: 0.105
D8: 32- HORAS | E8: =O34 -> 2500 | F8: =O35 -> 2330 | G8: =O38 -> 2444 | H8: =O41 -> 2535 | I8: =O44 -> 2489 | J8: =O47 -> 0 | K8: =O50 -> 0 | L8: =O53 -> 0 | M8: =O56 -> 0 | N8: =O59 -> 0 | O8: =O62 -> 0 | P8: =O65 -> 0 | Q8: =O68 -> 12298
D9: 20- PRODUTIVIDADE | E9: =E5/E7 -> 75.089657 | F9: =F5/F7 -> 73.970605 | G9: =G5/G7 -> 72.470163 | H9: =H5/H7 -> 66.431488 | I9: =I5/I7 -> 74.835515 | J9: =J5/J7 -> #DIV/0! | K9: =K5/K7 -> #DIV/0! | L9: =L5/L7 -> #DIV/0! | ... Q9: =Q5/Q7 -> 160.77619
D10: 32-PRODUTIVIDADE | E10: =E6/E8 -> 62.9584 | F10: =F6/F8 -> 61.44206 | G10: =G6/G8 -> 62.671031 | H10: =H6/H8 -> 56.362525 | I10: =I6/I8 -> 65.077943 | J10: =J6/J8 -> #DIV/0! | K10: =K6/K8 -> #DIV/0! | L10: =L6/L8 -> #DIV/0! | ... Q10: =Q6/Q8 -> 145.45333
D11: 20- MO | E11: =F34 -> 0.1123 | F11: =F35 -> 0.1107 | G11: =F38 -> 0.1142 | H11: =F41 -> 0.1068 | I11: =F44 -> 0.1064 | J11: =F47 -> 0 | K11: =F50 -> 0 | L11: =F53 -> 0 | M11: =F56 -> 0 | N11: =F59 -> 0 | O11: =F62 -> 0 | P11: =F65 -> 0
D12: 32- MO | E12: =Q34 -> 0.1204 | F12: =Q35 -> 0.1254 | G12: =Q38 -> 0.1184 | H12: =Q41 -> 0.1302 | I12: =Q44 -> 0.1218 | J12: =Q47 -> 0 | K12: =Q50 -> 0 | L12: =Q53 -> 0 | M12: =Q56 -> 0 | N12: =Q59 -> 0 | O12: =Q62 -> 0 | P12: =Q65 -> 0
H18: 60
H19: 55
B30: EVOLUÇÃO MENSAL DE HORAS
B32: COMPARAÇÃO DE CUSTOS AMADORA | M32: COMPARAÇÃO DE CUSTOS QUELUZ
C33: VENDAS | D33: HORAS | E33: PRODUTIVIDADE | F33: MO | N33: VENDAS | O33: HORAS | P33: PRODUTIVIDADE | Q33: MO
B34: JANEIRO | C34: =Serviço!C70 -> 288945 | D34: 3848 | E34: =C34/D34 -> 75.089657 | F34: 0.1123 | M34: JANEIRO | N34: =Serviço!C81 -> 157396 | O34: 2500 | P34: =N34/O34 -> 62.9584 | Q34: 0.1204
B35: FEVEREIRO | C35: =Serviço!D70 -> 254163 | D35: 3436 | E35: =C35/D35 -> 73.970605 | F35: 0.1107 | M35: FEVEREIRO | N35: =Serviço!D81 -> 143160 | O35: 2330 | P35: =N35/O35 -> 61.44206 | Q35: 0.1254
B36: ⃤ ABSOLUTA | C36: =C35-C34 -> -34782 | D36: =D35-D34 -> -412 | E36: =E35-E34 -> -1.1190516 | F36: =(F35-F34)*100 -> -0.16 | M36: ⃤ ABSOLUTA PP | N36: =N35-N34 -> -14236 | O36: =O35-O34 -> -170 | P36: =P35-P34 -> -1.5163399 | Q36: =(Q35-Q34)*100 -> 0.5
B37: ⃤ RELATIVA | C37: =C36/C34 -> -0.12037585 | D37: =D36/D34 -> -0.10706861 | E37: =E36/E35 -> -0.015128328 | F37: =(F35-F34)/F34 -> -0.014247551 | M37: ⃤ RELATIVA | N37: =N36/N34 -> -0.090447025 | O37: =O36/O34 -> -0.068 | P37: =P36/P35 -> -0.024679184 | Q37: =(Q35-Q34)/Q34 -> 0.041528239
B38: MARÇO | C38: =Serviço!E70 -> 280532 | D38: 3871 | E38: =C38/D38 -> 72.470163 | F38: 0.1142 | M38: MARÇO | N38: =Serviço!E81 -> 153168 | O38: 2444 | P38: =N38/O38 -> 62.671031 | Q38: 0.1184
B39: ⃤ ABSOLUTA | C39: =C38-C35 -> 26369 | D39: =D38-D35 -> 435 | E39: =E38-E35 -> -1.5004426 | F39: =(F38-F35)*100 -> 0.35 | M39: ⃤ ABSOLUTA PP | N39: =N38-N35 -> 10008 | O39: =O38-O35 -> 114 | P39: =P38-P35 -> 1.228971 | Q39: =(Q38-Q35)*100 -> -0.7
B40: ⃤ RELATIVA | C40: =C39/C35 -> 0.10374838 | D40: =D39/D35 -> 0.1266007 | E40: =E39/E35 -> -0.020284309 | F40: =(F38-F35)/F35 -> 0.031616983 | M40: ⃤ RELATIVA | N40: =N39/N35 -> 0.069907795 | O40: =O39/O35 -> 0.048927039 | P40: =P39/P35 -> 0.020002113 | Q40: =(Q38-Q35)/Q35 -> -0.055821372
B41: ABRIL | C41: =Serviço!F70 -> 247258 | D41: 3722 | E41: =C41/D41 -> 66.431488 | F41: 0.1068 | M41: ABRIL | N41: =Serviço!F81 -> 142879 | O41: 2535 | P41: =N41/O41 -> 56.362525 | Q41: 0.1302
B42: ⃤ ABSOLUTA | C42: =C41-C38 -> -33274 | D42: =D41-D38 -> -149 | E42: =E41-E38 -> -6.0386743 | F42: =(F41-F38)*100 -> -0.74 | M42: ⃤ ABSOLUTA PP | N42: =N41-N38 -> -10289 | O42: =O41-O38 -> 91 | P42: =P41-P38 -> -6.3085064 | Q42: =(Q41-Q38)*100 -> 1.18
B43: ⃤ RELATIVA | C43: =C42/C38 -> -0.11861035 | D43: =D42/D38 -> -0.038491346 | E43: =E42/E38 -> -0.083326352 | F43: =(F41-F38)/F38 -> -0.064798599 | M43: ⃤ RELATIVA | N43: =N42/N38 -> -0.067174606 | O43: =O42/O38 -> 0.037234043 | P43: =P42/P38 -> -0.10066065 | Q43: =(Q41-Q38)/Q38 -> 0.099662162
B44: MAIO | C44: =Serviço!G70 -> 251597 | D44: 3362 | E44: =C44/D44 -> 74.835515 | F44: 0.1064 | M44: MAIO | N44: =Serviço!G81 -> 161979 | O44: 2489 | P44: =N44/O44 -> 65.077943 | Q44: 0.1218
B45: ⃤ ABSOLUTA | C45: =C44-C41 -> 4339 | D45: =D44-D41 -> -360 | E45: =E44-E41 -> 8.4040261 | F45: =(F44-F41)*100 -> -0.04 | M45: ⃤ ABSOLUTA PP | N45: =N44-N41 -> 19100 | O45: =O44-O41 -> -46 | P45: =P44-P41 -> 8.7154183 | Q45: =(Q44-Q41)*100 -> -0.84
B46: ⃤ RELATIVA | C46: =C45/C41 -> 0.017548472 | D46: =D45/D41 -> -0.096722192 | E46: =E45/E41 -> 0.12650667 | F46: =(F44-F41)/F41 -> -0.0037453184 | M46: ⃤ RELATIVA | N46: =N45/N41 -> 0.13367955 | O46: =O45/O41 -> -0.018145957 | P46: =P45/P41 -> 0.15463144 | Q46: =(Q44-Q41)/Q41 -> -0.064516129
B47: JUNHO | C47: =Serviço!H70 -> 252397 | E47: =C47/D47 -> #DIV/0! | M47: JUNHO | N47: =Serviço!H81 -> 159094 | P47: =N47/O47 -> #DIV/0!
B48: ⃤ ABSOLUTA | C48: =C47-C44 -> 800 | D48: =D47-D44 -> -3362 | E48: =E47-E44 -> #DIV/0! | F48: =(F47-F44)*100 -> -10.64 | M48: ⃤ ABSOLUTA PP | N48: =N47-N44 -> -2885 | O48: =O47-O44 -> -2489 | P48: =P47-P44 -> #DIV/0! | Q48: =(Q47-Q44)*100 -> -12.18
B49: ⃤ RELATIVA | C49: =C48/C44 -> 0.0031796882 | D49: =D48/D44 -> -1 | E49: =E48/E44 -> #DIV/0! | F49: =(F47-F44)/F44 -> -1 | M49: ⃤ RELATIVA | N49: =N48/N44 -> -0.017810951 | O49: =O48/O44 -> -1 | P49: =P48/P44 -> #DIV/0! | Q49: =(Q47-Q44)/Q44 -> -1
B50: JULHO | C50: =Serviço!I70 -> 268928 | E50: =C50/D50 -> #DIV/0! | M50: JULHO | N50: =Serviço!I81 -> 165280 | P50: =N50/O50 -> #DIV/0!
B51: ⃤ ABSOLUTA | C51: =C50-C47 -> 16531 | D51: =D50-D47 -> 0 | E51: =E50-E47 -> #DIV/0! | F51: =(F50-F47)*100 -> 0 | M51: ⃤ ABSOLUTA PP | N51: =N50-N34 -> 7884 | O51: =O50-O34 -> -2500 | P51: =P50-P47 -> #DIV/0! | Q51: =(Q50-Q47)*100 -> 0
B52: ⃤ RELATIVA | C52: =C51/C47 -> 0.065496024 | D52: =D51/D47 -> #DIV/0! | E52: =E51/E47 -> #DIV/0! | F52: =(F50-F47)/F47 -> #DIV/0! | M52: ⃤ RELATIVA | N52: =N51/N34 -> 0.050090218 | O52: =O51/O34 -> -1 | P52: =P51/P47 -> #DIV/0! | Q52: =(Q50-Q47)/Q47 -> #DIV/0!
B53: AGOSTO | C53: =Serviço!J70 -> 286413 | E53: =C53/D53 -> #DIV/0! | M53: AGOSTO | N53: =Serviço!J81 -> 168534 | P53: =N53/O53 -> #DIV/0!
B54: ⃤ ABSOLUTA | C54: =C53-C50 -> 17485 | D54: =D53-D50 -> 0 | E54: =E53-E50 -> #DIV/0! | F54: =(F53-F50)*100 -> 0 | M54: ⃤ ABSOLUTA PP | N54: =N53-N50 -> 3254 | O54: =O53-O50 -> 0 | P54: =P53-P50 -> #DIV/0! | Q54: =(Q53-Q50)*100 -> 0
B55: ⃤ RELATIVA | C55: =C54/C50 -> 0.065017402 | D55: =D54/D50 -> #DIV/0! | E55: =E54/E50 -> #DIV/0! | F55: =(F53-F50)/F50 -> #DIV/0! | M55: ⃤ RELATIVA | N55: =N54/N50 -> 0.019687803 | O55: =O54/O50 -> #DIV/0! | P55: =P54/P50 -> #DIV/0! | Q55: =(Q53-Q50)/Q50 -> #DIV/0!
B56: SETEMBRO | C56: =Serviço!K70 -> 246748 | E56: =C56/D56 -> #DIV/0! | M56: SETEMBRO | N56: =Serviço!K81 -> 155517 | P56: =N56/O56 -> #DIV/0!
B57: ⃤ ABSOLUTA | C57: =C56-C53 -> -39665 | D57: =D56-D53 -> 0 | E57: =E56-E53 -> #DIV/0! | F57: =(F56-F53)*100 -> 0 | M57: ⃤ ABSOLUTA PP | N57: =N56-N53 -> -13017 | O57: =O56-O53 -> 0 | P57: =P56-P53 -> #DIV/0! | Q57: =(Q56-Q53)*100 -> 0
B58: ⃤ RELATIVA | C58: =C57/C53 -> -0.13848883 | D58: =D57/D53 -> #DIV/0! | E58: =E57/E53 -> #DIV/0! | F58: =(F56-F53)/F53 -> #DIV/0! | M58: ⃤ RELATIVA | N58: =N57/N53 -> -0.077236641 | O58: =O57/O53 -> #DIV/0! | P58: =P57/P53 -> #DIV/0! | Q58: =(Q56-Q53)/Q53 -> #DIV/0!
...

Sheet Produto
B2: CUSTO DE VENDAS
C3: JANEIRO | D3: FEVEREIRO | E3: MARÇO | F3: ABRIL | G3: MAIO | H3: JUNHO | I3: JULHO | J3: AGOSTO | K3: SETEMBRO | L3: OUTUBRO | M3: NOVEMBRO | N3: DEZEMBRO | O3: ANO | P3: LY
A4: OBJETIVO | B4: COMIDA (20) | C4: 0.2576 | D4: 0.26 | E4: 0.2613 | F4: 0.2613
B5: PAPEL (20) | C5: 0.0159 | D5: 0.0312 | E5: 0.0308 | F5: 0.031
A6: 0.007 | B6: REFEIÇÕES (20) | C6: 0.0082 | D6: 0.009 | E6: 0.0091 | F6: 0.008
A7: 0.005 | B7: PERDAS (20) | C7: 0.0052 | D7: 0.005 | E7: 0.005 | F7: 0.005
B8: PROMOS (20) | C8: 0.0017 | D8: 0.0024 | E8: 0.0027 | F8: 0.002
B9: C.VENDAS (20) | C9: 0.2903 | D9: 0.31 | E9: 0.2772 | F9: 0.3061
B10: COMIDA (32) | C10: 0.2494 | D10: 0.2671 | E10: 0.2723 | F10: 0.2547
B11: PAPEL (32) | C11: 0.03 | D11: 0.0314 | E11: 0.0339 | F11: 0.0338
A12: 0.008 | B12: REFEIÇÕES (32) | C12: 0.0105 | D12: 0.0095 | E12: 0.0089 | F12: 0.0098
A13: 0.005 | B13: PERDAS (32) | C13: 0.0071 | D13: 0.0074 | E13: 0.0069 | F13: 0.0086
B14: PROMOS (32) | C14: 0.0025 | D14: 0.0027 | E14: 0.0033 | F14: 0.0028
B15: C.VENDAS (32) | C15: 0.302 | D15: 0.3181 | E15: 0.3253 | F15: 0.3097
B31: DESVIOS
C32: PÃO REG | E32: CARNE REG | G32: CARNE ROYAL | I32: CHK OPT | K32: CHK NUGGETS | M32: BACON FATIAS | O32: COMPAL M/L | Q32: QUEIJO CHEDDAR | S32: QUEIJO EMMENTAL/WHITE
C33: 20 | D33: 32 | E33: 20 | F33: 32 | G33: 20 | H33: 32 | I33: 20 | J33: 32 | K33: 20 | L33: 32 | M33: 20 | N33: 32 | O33: 20 | P33: 32 | Q33: 20 | R33: 32 | S33: 20 | T33: 32
B34: JANEIRO | C34: -293 | D34: -62 | E34: -75 | F34: 16 | G34: -62 | H34: -20 | I34: 19 | J34: -9 | K34: -40 | L34: -9 | M34: 203 | N34: 70 | O34: -11 | P34: -16 | Q34: 280 | R34: -274 | S34: -21 | T34: -59
B35: FEVEREIRO | C35: -177 | D35: -77 | E35: 126 | F35: -95 | G35: 94 | H35: 10 | I35: 25 | J35: -16 | K35: -472 | L35: -334 | M35: -567 | N35: 254 | O35: -24 | P35: -17 | Q35: -509 | R35: -148 | S35: -130 | T35: -68
B36: ⃤ ABSOLUTA | C36: 116 | D36: -15 | E36: 201 | F36: -111 | G36: 156 | H36: 30 | I36: 6 | J36: -7 | K36: -432 | L36: -325 | M36: -770 | N36: 184 | O36: -13 | P36: -1 | Q36: -789 | R36: 126 | S36: -109 | T36: -9
B37: ⃤ RELATIVA | C37: 0.4 | D37: -0.24 | E37: -2.68 | F37: -6.94 | G37: 2.52 | H37: 1.5 | I37: -0.32 | J37: -0.78 | K37: 10.8 | L37: 36.11 | M37: 3.79 | N37: -2.63 | O37: -1.18 | P37: -0.06 | Q37: 2.82 | R37: 0.46 | S37: -5.19 | T37: -0.15
B38: MARÇO | C38: -45 | D38: -133 | E38: -14 | F38: -146 | G38: 61 | H38: -15 | I38: -33 | J38: -18 | K38: -358 | L38: -245 | M38: 623 | N38: 202 | O38: -31 | P38: -24 | Q38: -107 | R38: -141 | S38: -92 | T38: -79
B39: ⃤ ABSOLUTA | C39: 132 | D39: -56 | E39: -140 | F39: -51 | G39: -33 | H39: -25 | I39: -58 | J39: -2 | K39: 114 | L39: 89 | M39: 1190 | N39: -52 | O39: -7 | P39: -7 | Q39: 402 | R39: 7 | S39: 38 | T39: -11
B40: ⃤ RELATIVA | C40: -0.75 | D40: 0.73 | E40: -1.11 | F40: 0.54 | G40: -0.35 | H40: -2.5 | I40: -2.32 | J40: 0.13 | K40: -0.24 | L40: -0.27 | N40: -0.2 | O40: 0.29 | P40: 0.41 | Q40: -0.79 | R40: -0.05 | S40: -0.29 | T40: 0.16
B41: ABRIL | C41: -172 | D41: -130 | E41: -107 | F41: -140 | G41: 76 | H41: -5 | I41: 497 | J41: -40 | K41: -656 | L41: -135 | M41: 429 | N41: 332 | O41: -14 | P41: -10 | Q41: -156 | R41: -157 | S41: -4 | T41: 12
B42: ⃤ ABSOLUTA | C42: -127 | D42: 3 | E42: -93 | F42: 6 | G42: 15 | H42: 10 | I42: 530 | J42: -22 | K42: -298 | L42: 110 | M42: -194 | N42: 130 | O42: 17 | P42: 14 | Q42: -49 | R42: -16 | S42: 88 | T42: 91
B43: ⃤ RELATIVA | C43: 2.82 | D43: -0.02 | E43: 6.64 | F43: -0.04 | G43: 0.25 | H43: -0.67 | I43: -16.06 | J43: 1.22 | K43: 0.83 | L43: -0.45 | M43: -0.31 | N43: 0.64 | O43: -0.55 | P43: -0.58 | Q43: 0.46 | R43: 0.11 | S43: -0.96 | T43: -1.15
B44: MAIO | C44: -86 | E44: 88 | G44: -16 | I44: 9 | K44: -516 | M44: -208 | O44: -16 | Q44: -61 | S44: 21
B45: ⃤ ABSOLUTA | C45: 86 | D45: 130 | E45: 195 | F45: 140 | G45: -92 | H45: 5 | I45: -488 | J45: 40 | K45: 140 | L45: 135 | M45: -637 | N45: -332 | O45: -2 | P45: 10 | Q45: 95 | R45: 157 | S45: 25 | T45: -12
B46: ⃤ RELATIVA | C46: -0.5 | D46: -1 | E46: -1.82 | F46: -1 | G46: -1.21 | H46: -1 | I46: -0.98 | J46: -1 | K46: -0.21 | L46: -1 | M46: -1.48 | N46: -1 | O46: 0.14 | P46: -1 | Q46: -0.61 | R46: -1 | S46: -6.25 | T46: -1
B47: JUNHO | C47: -200 | D47: -57 | E47: -4 | F47: -85 | G47: -47 | H47: -42 | I47: 67 | J47: -12 | K47: -13 | L47: 87 | M47: 634 | N47: 89 | O47: -26 | P47: -3 | Q47: -310 | R47: -136 | T47: -105
B48: ⃤ ABSOLUTA | C48: =C47-C44 -> -114 | D48: =D47-D44 -> -57 | E48: =E47-E44 -> -92 | F48: =F47-F44 -> -85 | G48: =G47-G44 -> -31 | H48: =H47-H44 -> -42 | I48: =I47-I44 -> 58 | J48: =J47-J44 -> -12 | ... T48: =T47-T44 -> -105
B49: ⃤ RELATIVA | C49: =C48/C44 -> 1.3255814 | D49: =D48/D44 -> #DIV/0! | E49: =E48/E44 -> -1.0454545 | F49: =F48/F44 -> #DIV/0! | G49: =G48/G44 -> 1.9375 | H49: =H48/H44 -> #DIV/0! | I49: =I48/I44 -> 6.4444444 | J49: =J48/J44 -> #DIV/0! | ... T49: =T48/T44 -> #DIV/0!
B50: JULHO | C50: 157 | D50: -50 | E50: 88 | F50: 102 | G50: -58 | H50: 9 | I50: -87 | J50: -11 | K50: -1207 | L50: -13 | M50: 885 | N50: 879 | O50: -34 | P50: 6 | Q50: -157 | R50: 42 | S50: -25 | T50: =-541+642 -> 101
B51: ⃤ ABSOLUTA | C51: =C50-C47 -> 357 | D51: =D50-D47 -> 7 | E51: =E50-E47 -> 92 | F51: =F50-F47 -> 187 | G51: =G50-G47 -> -11 | H51: =H50-H47 -> 51 | I51: =I50-I47 -> -154 | J51: =J50-J47 -> 1 | ... T51: =T50-T47 -> 206
B52: ⃤ RELATIVA | C52: =C51/C47 -> -1.785 | D52: =D51/D47 -> -0.12280702 | E52: =E51/E47 -> -23 | F52: =F51/F47 -> -2.2 | G52: =G51/G47 -> 0.23404255 | H52: =H51/H47 -> -1.2142857 | I52: =I51/I47 -> -2.2985075 | J52: =J51/J47 -> -0.083333333 | ... T52: =T51/T47 -> -1.9619048
B53: AGOSTO
B54: ⃤ ABSOLUTA | C54: =C53-C50 -> -157 | D54: =D53-D50 -> 50 | E54: =E53-E50 -> -88 | F54: =F53-F50 -> -102 | G54: =G53-G50 -> 58 | H54: =H53-H50 -> -9 | I54: =I53-I50 -> 87 | J54: =J53-J50 -> 11 | ... T54: =T53-T50 -> -101
B55: ⃤ RELATIVA | C55: =C54/C50 -> -1 | D55: =D54/D50 -> -1 | E55: =E54/E50 -> -1 | F55: =F54/F50 -> -1 | G55: =G54/G50 -> -1 | H55: =H54/H50 -> -1 | I55: =I54/I50 -> -1 | J55: =J54/J50 -> -1 | ... T55: =T54/T50 -> -1
B56: SETEMBRO
...

Sheet Manutenção
D2: ANÁLISE DE CUSTOS
E3: JANEIRO | F3: FEVEREIRO | G3: MARÇO | H3: ABRIL | I3: MAIO | J3: JUNHO | K3: JULHO | L3: AGOSTO | M3: SETEMBRO | N3: OUTUBRO | O3: NOVEMBRO | P3: DEZEMBRO | Q3: ANO
D4: 20- VENDAS | E4: =Serviço!C70 -> 288945 | F4: =Serviço!D70 -> 254163 | G4: =Serviço!E70 -> 280532 | H4: =Serviço!F70 -> 247258 | I4: =Serviço!G70 -> 251597 | J4: =Serviço!H70 -> 252397 | K4: =Serviço!I70 -> 268928 | L4: =Serviço!J70 -> 286413 | ... P4: =Serviço!N70 -> 82979 | Q4: =SUM(E4:P4) -> 2932397
D5: 32- VENDAS | E5: =Serviço!C81 -> 157396 | F5: =Serviço!D81 -> 143160 | G5: =Serviço!E81 -> 153168 | H5: =Serviço!F81 -> 142879 | I5: =Serviço!G81 -> 161979 | J5: =Serviço!H81 -> 159094 | K5: =Serviço!I81 -> 165280 | L5: =Serviço!J81 -> 168534 | ... P5: =Serviço!N81 -> 57366 | Q5: =SUM(E5:P5) -> 1788785
D6: 20- GASTOS GERAIS | E6: 2584 | Q6: =SUM(E6:P6) -> 2584
D7: 20- OPS | E7: 2962 | Q7: =SUM(E7:P7) -> 2962
D8: 20- MAN&REP | E8: 2648 | Q8: =SUM(E8:P8) -> 2648
D9: 32- GASTOS GERAIS | E9: 1821 | Q9: =SUM(E9:P9) -> 1821
D10: 32- OPS | E10: 2132 | Q10: =SUM(E10:P10) -> 2132
D11: 32- MAN&REP | E11: 790 | Q11: =SUM(E11:P11) -> 790
D31: GASTOS GERAIS
E32: JANEIRO | F32: FEVEREIRO | G32: MARÇO | H32: ABRIL | I32: MAIO | J32: JUNHO | K32: JULHO | L32: AGOSTO | M32: SETEMBRO | N32: OUTUBRO | O32: NOVEMBRO | P32: DEZEMBRO | Q32: ANO
D33: 20-ÁGUA | E33: 118 | Q33: =SUM(E33:P33) -> 118
D34: 20-ELETRICIDADE | E34: 1478 | Q34: =SUM(E34:P34) -> 1478
D35: 32-ÁGUA | E35: 128 | Q35: =SUM(E35:P35) -> 128
D36: 32-ELETRICIDADE | E36: 1135 | Q36: =SUM(E36:P36) -> 1135
C37: OBJETIVO | D37: 20- KW 22 vs 23 | E37: =27283-27548 -> -265 | Q37: =SUM(E37:P37) -> -265
C38: = ou > a 2022 | D38: 32- KW 22 vs 23 | E38: =21033-20809 -> 224 | Q38: =SUM(E38:P38) -> 224
A56: OPS
C57: EASY WASH | E57: APC | G57: LIQUÍDO WC | I57: GRILL CLEANER | K57: MASCARAS | M57: GEL DA MÃOS | O57: SACOS DO LIXO | Q57: ESFREGÃO | S57: SOLID FLOORCARE
C58: ∆ ABSOLUTA | D58: ∆ RELATIVA | E58: ∆ ABSOLUTA | F58: ∆ RELATIVA | G58: ∆ ABSOLUTA | H58: ∆ RELATIVA | I58: ∆ ABSOLUTA | J58: ∆ RELATIVA | K58: ∆ ABSOLUTA | L58: ∆ RELATIVA | M58: ∆ ABSOLUTA | N58: ∆ RELATIVA | O58: ∆ ABSOLUTA | P58: ∆ RELATIVA | Q58: ∆ ABSOLUTA | R58: ∆ RELATIVA | S58: ∆ ABSOLUTA | T58: ∆ RELATIVA
A59: JANEIRO | B59: AMADORA | C59: -37 | E59: -1 | G59: 6 | I59: -35 | K59: -3 | M59: -3 | O59: -13 | Q59: -4 | S59: -2
B60: QUELUZ | C60: -57 | E60: -1 | G60: 0 | I60: -24 | K60: -1 | M60: -1 | O60: -351 | Q60: -5 | S60: -1
A61: FEVEREIRO | B61: AMADORA | C61: -51 | D61: =(C61-C59)/C59 -> 0.37837838 | E61: -1 | F61: =(E61-E59)/E59 -> 0 | G61: -1 | H61: =(G61-G59)/G59 -> -1.1666667 | I61: -45 | J61: =(I61-I59)/I59 -> 0.28571429 | K61: -3 | L61: =(K61-K59)/K59 -> 0 | M61: -3 | N61: =(M61-M59)/M59 -> 0 | O61: -260 | P61: =(O61-O59)/O59 -> 19 | Q61: -7 | R61: =(Q61-Q59)/Q59 -> 0.75 | S61: -3 | T61: =(S61-S59)/S59 -> 0.5
B62: QUELUZ | C62: -122 | D62: =(C62-C60)/C60 -> 1.1403509 | E62: -1 | F62: =(E62-E60)/E60 -> 0 | G62: 1 | H62: =(G62-G60)/G60 -> #DIV/0! | I62: 5 | J62: =(I62-I60)/I60 -> -1.2083333 | K62: 0 | L62: =(K62-K60)/K60 -> -1 | M62: 0 | N62: =(M62-M60)/M60 -> -1 | O62: 106 | P62: =(O62-O60)/O60 -> -1.3019943 | Q62: 1 | R62: =(Q62-Q60)/Q60 -> -1.2 | S62: 0 | T62: =(S62-S60)/S60 -> -1
A63: MARÇO | B63: AMADORA | D63: =(C63-C61)/C61 -> -1 | F63: =(E63-E61)/E61 -> -1 | H63: =(G63-G61)/G61 -> -1 | J63: =(I63-I61)/I61 -> -1 | L63: =(K63-K61)/K61 -> -1 | N63: =(M63-M61)/M61 -> -1 | P63: =(O63-O61)/O61 -> -1 | R63: =(Q63-Q61)/Q61 -> -1 | T63: =(S63-S61)/S61 -> -1
B64: QUELUZ | D64: =(C64-C62)/C62 -> -1 | F64: =(E64-E62)/E62 -> -1 | H64: =(G64-G62)/G62 -> -1 | J64: =(I64-I62)/I62 -> -1 | L64: =(K64-K62)/K62 -> #DIV/0! | N64: =(M64-M62)/M62 -> #DIV/0! | P64: =(O64-O62)/O62 -> -1 | R64: =(Q64-Q62)/Q62 -> -1 | T64: =(S64-S62)/S62 -> #DIV/0!
A65: ABRIL | B65: AMADORA | D65: =(C65-C63)/C63 -> #DIV/0! | F65: =(E65-E63)/E63 -> #DIV/0! | H65: =(G65-G63)/G63 -> #DIV/0! | J65: =(I65-I63)/I63 -> #DIV/0! | L65: =(K65-K63)/K63 -> #DIV/0! | N65: =(M65-M63)/M63 -> #DIV/0! | P65: =(O65-O63)/O63 -> #DIV/0! | R65: =(Q65-Q63)/Q63 -> #DIV/0! | T65: =(S65-S63)/S63 -> #DIV/0!
B66: QUELUZ | D66: =(C66-C64)/C64 -> #DIV/0! | F66: =(E66-E64)/E64 -> #DIV/0! | H66: =(G66-G64)/G64 -> #DIV/0! | J66: =(I66-I64)/I64 -> #DIV/0! | L66: =(K66-K64)/K64 -> #DIV/0! | N66: =(M66-M64)/M64 -> #DIV/0! | P66: =(O66-O64)/O64 -> #DIV/0! | R66: =(Q66-Q64)/Q64 -> #DIV/0! | T66: =(S66-S64)/S64 -> #DIV/0!
A67: MAIO | B67: AMADORA | D67: =(C67-C65)/C65 -> #DIV/0! | F67: =(E67-E65)/E65 -> #DIV/0! | H67: =(G67-G65)/G65 -> #DIV/0! | J67: =(I67-I65)/I65 -> #DIV/0! | L67: =(K67-K65)/K65 -> #DIV/0! | N67: =(M67-M65)/M65 -> #DIV/0! | P67: =(O67-O65)/O65 -> #DIV/0! | R67: =(Q67-Q65)/Q65 -> #DIV/0! | T67: =(S67-S65)/S65 -> #DIV/0!
B68: QUELUZ | D68: =(C68-C66)/C66 -> #DIV/0! | F68: =(E68-E66)/E66 -> #DIV/0! | H68: =(G68-G66)/G66 -> #DIV/0! | J68: =(I68-I66)/I66 -> #DIV/0! | L68: =(K68-K66)/K66 -> #DIV/0! | N68: =(M68-M66)/M66 -> #DIV/0! | P68: =(O68-O66)/O66 -> #DIV/0! | R68: =(Q68-Q66)/Q66 -> #DIV/0! | T68: =(S68-S66)/S66 -> #DIV/0!
A69: JUNHO | B69: AMADORA | D69: =(C69-C67)/C67 -> #DIV/0! | F69: =(E69-E67)/E67 -> #DIV/0! | H69: =(G69-G67)/G67 -> #DIV/0! | J69: =(I69-I67)/I67 -> #DIV/0! | L69: =(K69-K67)/K67 -> #DIV/0! | N69: =(M69-M67)/M67 -> #DIV/0! | P69: =(O69-O67)/O67 -> #DIV/0! | R69: =(Q69-Q67)/Q67 -> #DIV/0! | T69: =(S69-S67)/S67 -> #DIV/0!
B70: QUELUZ | D70: =(C70-C68)/C68 -> #DIV/0! | F70: =(E70-E68)/E68 -> #DIV/0! | H70: =(G70-G68)/G68 -> #DIV/0! | J70: =(I70-I68)/I68 -> #DIV/0! | L70: =(K70-K68)/K68 -> #DIV/0! | N70: =(M70-M68)/M68 -> #DIV/0! | P70: =(O70-O68)/O68 -> #DIV/0! | R70: =(Q70-Q68)/Q68 -> #DIV/0! | T70: =(S70-S68)/S68 -> #DIV/0!
A71: JULHO | B71: AMADORA | D71: =(C71-C69)/C69 -> #DIV/0! | F71: =(E71-E69)/E69 -> #DIV/0! | H71: =(G71-G69)/G69 -> #DIV/0! | J71: =(I71-I69)/I69 -> #DIV/0! | L71: =(K71-K69)/K69 -> #DIV/0! | N71: =(M71-M69)/M69 -> #DIV/0! | P71: =(O71-O69)/O69 -> #DIV/0! | R71: =(Q71-Q69)/Q69 -> #DIV/0! | T71: =(S71-S69)/S69 -> #DIV/0!
B72: QUELUZ | D72: =(C72-C70)/C70 -> #DIV/0! | F72: =(E72-E70)/E70 -> #DIV/0! | H72: =(G72-G70)/G70 -> #DIV/0! | J72: =(I72-I70)/I70 -> #DIV/0! | L72: =(K72-K70)/K70 -> #DIV/0! | N72: =(M72-M70)/M70 -> #DIV/0! | P72: =(O72-O70)/O70 -> #DIV/0! | R72: =(Q72-Q70)/Q70 -> #DIV/0! | T72: =(S72-S70)/S70 -> #DIV/0!
A73: AGOSTO | B73: AMADORA | D73: =(C73-C71)/C71 -> #DIV/0! | F73: =(E73-E71)/E71 -> #DIV/0! | H73: =(G73-G71)/G71 -> #DIV/0! | J73: =(I73-I71)/I71 -> #DIV/0! | L73: =(K73-K71)/K71 -> #DIV/0! | N73: =(M73-M71)/M71 -> #DIV/0! | P73: =(O73-O71)/O71 -> #DIV/0! | R73: =(Q73-Q71)/Q71 -> #DIV/0! | T73: =(S73-S71)/S71 -> #DIV/0!
B74: QUELUZ | D74: =(C74-C72)/C72 -> #DIV/0! | F74: =(E74-E72)/E72 -> #DIV/0! | H74: =(G74-G72)/G72 -> #DIV/0! | J74: =(I74-I72)/I72 -> #DIV/0! | L74: =(K74-K72)/K72 -> #DIV/0! | N74: =(M74-M72)/M72 -> #DIV/0! | P74: =(O74-O72)/O72 -> #DIV/0! | R74: =(Q74-Q72)/Q72 -> #DIV/0! | T74: =(S74-S72)/S72 -> #DIV/0!
A75: SETEMBRO | B75: AMADORA | D75: =(C75-C73)/C73 -> #DIV/0! | F75: =(E75-E73)/E73 -> #DIV/0! | H75: =(G75-G73)/G73 -> #DIV/0! | J75: =(I75-I73)/I73 -> #DIV/0! | L75: =(K75-K73)/K73 -> #DIV/0! | N75: =(M75-M73)/M73 -> #DIV/0! | P75: =(O75-O73)/O73 -> #DIV/0! | R75: =(Q75-Q73)/Q73 -> #DIV/0! | T75: =(S75-S73)/S73 -> #DIV/0!
B76: QUELUZ | D76: =(C76-C74)/C74 -> #DIV/0! | F76: =(E76-E74)/E74 -> #DIV/0! | H76: =(G76-G74)/G74 -> #DIV/0! | J76: =(I76-I74)/I74 -> #DIV/0! | L76: =(K76-K74)/K74 -> #DIV/0! | N76: =(M76-M74)/M74 -> #DIV/0! | P76: =(O76-O74)/O74 -> #DIV/0! | R76: =(Q76-Q74)/Q74 -> #DIV/0! | T76: =(S76-S74)/S74 -> #DIV/0!
A77: OUTUBRO | B77: AMADORA | D77: =(C77-C75)/C75 -> #DIV/0! | F77: =(E77-E75)/E75 -> #DIV/0! | H77: =(G77-G75)/G75 -> #DIV/0! | J77: =(I77-I75)/I75 -> #DIV/0! | L77: =(K77-K75)/K75 -> #DIV/0! | N77: =(M77-M75)/M75 -> #DIV/0! | P77: =(O77-O75)/O75 -> #DIV/0! | R77: =(Q77-Q75)/Q75 -> #DIV/0! | T77: =(S77-S75)/S75 -> #DIV/0!
...

Sheet BSV
B1: Desempenho de Gerentes
B2: Dados | F2: Secções de avaliação
B3: Data | D3: Loja | E3: Gerente | F3: =[1]Original!$A$2 -> Limpeza e Higienização | G3: =[1]Original!$A$3 -> Prevenção e Contaminação | H3: =[1]Original!$A$4 -> Armazenamento | I3: =[1]Original!$A$5 -> Confeção | J3: =[1]Original!$A$6 -> Geral | K3: Máquinas de Gelado e BIC | L3: Lista de Controlo Diário | M3: Controlos de Gestão | N3: Nota final
A4: Janeiro | B4: 22-jan. | C4: 0 | D4: 20 | E4: Uilson | F4: 1 | G4: 0.8 | H4: 0.7368 | I4: 1 | J4: 1 | K4: 0.895 | N4: 0.895 | O4: Bruna | P4: =AVERAGEIFS(N$4:N$28,E$4:E$28,"Bruna") -> #DIV/0!
B5: 31-jan. | C5: 0 | D5: 32 | E5: Marília | F5: 1 | G5: 0.7 | H5: 0.7368 | I5: 1 | J5: 1 | K5: 0.867 | N5: 0.867 | O5: Claudia | P5: =AVERAGEIFS(N$4:N$28,E$4:E$28,"Claudia") -> #DIV/0!
A6: Fevereiro | B6: 2-fev. | C6: 0 | D6: 20 | E6: Uilson | F6: 0.7619 | G6: 0.6 | H6: 0.7368 | I6: 1 | J6: 0.8333 | K6: 0.743 | N6: 0.743 | O6: Hugo | P6: =AVERAGEIFS(N$4:N$28,E$4:E$28,"Hugo") -> #DIV/0!
B7: 16-fev. | C7: 0 | D7: 20 | E7: Isabel | F7: 1 | G7: 0.74 | H7: 0.5 | I7: 1 | J7: 1 | K7: 0.821 | N7: 0.821 | O7: Isaac | P7: =AVERAGEIFS(N$4:N$28,E$4:E$28,"Isaac") -> #DIV/0!
B8: 22-fev. | C8: 1 | D8: 32 | E8: Vitor | F8: 0.86 | G8: 1 | H8: 0.74 | I8: 1 | J8: 1 | N8: 0.924
A9: Março | B9: 15-mar. | C9: 0 | D9: 20 | E9: Isabel | F9: 0.85714286 | G9: 0.7 | H9: 0.57894737 | I9: 1 | J9: 1 | N9: 0.75 | O9: Isabel | P9: =AVERAGEIFS(N$4:N$28,E$4:E$28,"Isabel") -> 0.7855
B10: 20-mar. | C10: 0 | D10: 32 | E10: Vitor | F10: 0.76190476 | G10: 0.7 | H10: 0.84210526 | I10: 1 | J10: 1 | N10: 0.75 | O10: Janice | P10: =AVERAGEIFS(N$4:N$28,E$4:E$28,"Janice") -> #DIV/0!
A11: Abril | C11: =IF(E11=B$30,1,0) -> 1 | O11: Luis | P11: =AVERAGEIFS(N$4:N$28,E$4:E$28,"Luis") -> #DIV/0!
C12: =IF(E12=B$30,1,0) -> 1 | O12: Marília | P12: =AVERAGEIFS(N$4:N$28,E$4:E$28,"Marília") -> 0.867
A13: Maio | C13: =IF(E13=B$30,1,0) -> 1 | O13: Uilson | P13: =AVERAGEIFS(N$4:N$28,E$4:E$28,"Uilson") -> 0.819
C14: =IF(E14=B$30,1,0) -> 1 | O14: Vitor | P14: =AVERAGEIFS(N$4:N$28,E$4:E$28,"Vitor") -> 0.837
A15: Junho | C15: =IF(E15=B$30,1,0) -> 1 | O15: William | P15: =AVERAGEIFS(N$4:N$28,E$4:E$28,"William") -> #DIV/0!
C16: =IF(E16=B$30,1,0) -> 1 | O16: Média | P16: =AVERAGE(P4:P15) -> #DIV/0!
A17: Julho | C17: =IF(E17=B$30,1,0) -> 1
C18: =IF(E18=B$30,1,0) -> 1
A19: Agosto | C19: =IF(E19=B$30,1,0) -> 1
C20: =IF(E20=B$30,1,0) -> 1
A21: Setembro | C21: =IF(E21=B$30,1,0) -> 1
C22: =IF(E22=B$30,1,0) -> 1
A23: Outubro | C23: =IF(E23=B$30,1,0) -> 1
C24: =IF(E24=B$30,1,0) -> 1
A25: Novembro | C25: =IF(E25=B$30,1,0) -> 1
C26: =IF(E26=B$30,1,0) -> 1
A27: Dezembro | C27: =IF(E27=B$30,1,0) -> 1
C28: =IF(E28=B$30,1,0) -> 1
A29: Média por área | F29: =AVERAGE(F4:F28) -> 0.89156395 | G29: =AVERAGE(G4:G28) -> 0.74857143 | H29: =AVERAGE(H4:H28) -> 0.6959218 | I29: =AVERAGE(I4:I28) -> 1 | J29: =AVERAGE(J4:J28) -> 0.97618571 | K29: =AVERAGE(K4:K28) -> 0.8315 | L29: =AVERAGE(L4:L28) -> #DIV/0! | M29: =AVERAGE(M4:M28) -> #DIV/0! | N29: =AVERAGE(N4:N28) -> 0.82142857
A30: Gerente | F30: =F34/F33 -> 0.045263158 | G30: =G34/G33 -> 0.052631579 | H30: =H34/H33 -> 0.038947368 | I30: =I34/I33 -> 0.052631579 | J30: =J34/J33 -> 0.052631579 | K30: =K34/K33 -> 0 | L30: =L34/L33 -> 0 | M30: =M34/M33 -> 0 | N30: =N34/N33 -> 0.048631579
F31: =COUNTIF($D4:$D28,$B35) -> 0 | G31: =COUNTIF($D4:$D28,$B35) -> 0 | H31: =COUNTIF($D4:$D28,$B35) -> 0 | I31: =COUNTIF($D4:$D28,$B35) -> 0 | J31: =COUNTIF($D4:$D28,$B35) -> 0 | K31: =COUNTIF($D4:$D28,$B35) -> 0 | L31: =COUNTIF($D4:$D28,$B35) -> 0 | M31: =COUNTIF($D4:$D28,$B35) -> 0 | N31: =COUNTIF($D4:$D28,$B35) -> 0
F32: =SUMIF(D4:D28,B35,F4:F28) -> 0 | G32: =SUMIF($D4:$D28,$B35,G4:G28) -> 0 | H32: =SUMIF($D4:$D28,$B35,H4:H28) -> 0 | I32: =SUMIF($D4:$D28,$B35,I4:I28) -> 0 | J32: =SUMIF($D4:$D28,$B35,J4:J28) -> 0 | K32: =SUMIF($D4:$D28,$B35,K4:K28) -> 0 | L32: =SUMIF($D4:$D28,$B35,L4:L28) -> 0 | M32: =SUMIF($D4:$D28,$B35,M4:M28) -> 0 | N32: =SUMIF($D4:$D28,$B35,N4:N28) -> 0
F33: =COUNTIF($C4:$C28,1) -> 19 | G33: =COUNTIF($C4:$C28,1) -> 19 | H33: =COUNTIF($C4:$C28,1) -> 19 | I33: =COUNTIF($C4:$C28,1) -> 19 | J33: =COUNTIF($C4:$C28,1) -> 19 | K33: =COUNTIF($C4:$C28,1) -> 19 | L33: =COUNTIF($C4:$C28,1) -> 19 | M33: =COUNTIF($C4:$C28,1) -> 19 | N33: =COUNTIF($C4:$C28,1) -> 19
F34: =SUMIF($C4:$C28,1,F4:F28) -> 0.86 | G34: =SUMIF($C4:$C28,1,G4:G28) -> 1 | H34: =SUMIF($C4:$C28,1,H4:H28) -> 0.74 | I34: =SUMIF($C4:$C28,1,I4:I28) -> 1 | J34: =SUMIF($C4:$C28,1,J4:J28) -> 1 | K34: =SUMIF($C4:$C28,1,K4:K28) -> 0 | L34: =SUMIF($C4:$C28,1,L4:L28) -> 0 | M34: =SUMIF($C4:$C28,1,M4:M28) -> 0 | N34: =SUMIF($C4:$C28,1,N4:N28) -> 0.924
A35: Loja | F35: =F32/F31 -> #DIV/0! | G35: =G32/G31 -> #DIV/0! | H35: =H32/H31 -> #DIV/0! | I35: =I32/I31 -> #DIV/0! | J35: =J32/J31 -> #DIV/0! | K35: =K32/K31 -> #DIV/0! | L35: =L32/L31 -> #DIV/0! | M35: =M32/M31 -> #DIV/0! | N35: =N32/N31 -> #DIV/0!
B36: Nota por dep. | F36: =AVERAGE(F4:H28) -> 0.77868573 | I36: =AVERAGE(I4:J28) -> 0.98809286 | L36: =AVERAGE(L4:N28) -> 0.82142857

Sheet VSC
B1: Desempenho de Gerentes
B2: Dados | F2: Secções de avaliação
B3: Data | C3: =IF(E3=B$29,1,0) -> 0 | D3: Loja | E3: Gerente | F3: =[1]Original!$A$2 -> Limpeza e Higienização | G3: =[1]Original!$A$3 -> Prevenção e Contaminação | H3: =[1]Original!$A$4 -> Armazenamento | I3: =[1]Original!$A$5 -> Confeção | J3: =[1]Original!$A$6 -> Geral | K3: Máquinas de Gelado e BIC | L3: Lista de Controlo Diário | M3: Controlos de Gestão | N3: Nota final
A4: Janeiro | B4: 45299 | C4: 1 | D4: 20 | E4: Bruna | F4: 1 | G4: 0.61 | H4: 0.5 | I4: 1 | J4: 1 | N4: 0.76 | O4: Bruna | P4: =AVERAGEIFS(N$4:N$27,E$4:E$27,"Bruna") -> 0.76
B5: 45313 | C5: 0 | D5: 32 | E5: Vitor | F5: 1 | G5: 0.61 | H5: 0.5 | I5: 1 | J5: 0.46 | N5: 0.68 | O5: Claudia | P5: =AVERAGEIFS(N$4:N$27,E$4:E$27,"Claudia") -> #DIV/0!
A6: Fevereiro | B6: 45324 | C6: 0 | D6: 32 | E6: Marilia | F6: 1 | G6: 0.5 | H6: 0.52 | I6: 0.81 | J6: 1 | N6: 0.68 | O6: Hugo | P6: =AVERAGEIFS(N$4:N$27,E$4:E$27,"Hugo") -> #DIV/0!
B7: 45338 | C7: 0 | D7: 20 | E7: Isabel | F7: 1 | G7: 0.74 | H7: 0.5 | I7: 1 | J7: 1 | K7: 0.5 | L7: 1 | M7: 1 | N7: 0.821 | O7: Isaac | P7: =AVERAGEIFS(N$4:N$27,E$4:E$27,"Isaac") -> #DIV/0!
A8: Março | C8: =IF(E8=B$29,1,0) -> 0 | O8: Isabel | P8: =AVERAGEIFS(N$4:N$27,E$4:E$27,"Isabel") -> 0.821
C9: =IF(E9=B$29,1,0) -> 0 | O9: Janice | P9: =AVERAGEIFS(N$4:N$27,E$4:E$27,"Janice") -> #DIV/0!
A10: Abril | C10: =IF(E10=B$29,1,0) -> 0 | O10: Luis | P10: =AVERAGEIFS(N$4:N$27,E$4:E$27,"Luis") -> #DIV/0!
C11: =IF(E11=B$29,1,0) -> 0 | O11: Marília | P11: =AVERAGEIFS(N$4:N$27,E$4:E$27,"Marília") -> #DIV/0!
A12: Maio | C12: =IF(E12=B$29,1,0) -> 0 | O12: Uilson | P12: =AVERAGEIFS(N$4:N$27,E$4:E$27,"Uilson") -> #DIV/0!
C13: =IF(E13=B$29,1,0) -> 0 | O13: Vitor | P13: =AVERAGEIFS(N$4:N$27,E$4:E$27,"Vitor") -> 0.68
A14: Junho | C14: =IF(E14=B$29,1,0) -> 0 | O14: William | P14: =AVERAGEIFS(N$4:N$27,E$4:E$27,"William") -> #DIV/0!
C15: =IF(E15=B$29,1,0) -> 0 | O15: Média | P15: =AVERAGE(P4:P14) -> #DIV/0!
A16: Julho | C16: =IF(E16=B$29,1,0) -> 0
C17: =IF(E17=B$29,1,0) -> 0
A18: Agosto | C18: =IF(E18=B$29,1,0) -> 0
C19: =IF(E19=B$29,1,0) -> 0
A20: Setembro | C20: =IF(E20=B$29,1,0) -> 0
C21: =IF(E21=B$29,1,0) -> 0
A22: Outubro | C22: =IF(E22=B$29,1,0) -> 0
C23: =IF(E23=B$29,1,0) -> 0
A24: Novembro | C24: =IF(E24=B$29,1,0) -> 0
C25: =IF(E25=B$29,1,0) -> 0
A26: Dezembro | C26: =IF(E26=B$29,1,0) -> 0
C27: =IF(E27=B$29,1,0) -> 0
A28: Média por área | F28: =AVERAGE(F4:F27) -> 1 | G28: =AVERAGE(G4:G27) -> 0.615 | H28: =AVERAGE(H4:H27) -> 0.505 | I28: =AVERAGE(I4:I27) -> 0.9525 | J28: =AVERAGE(J4:J27) -> 0.865 | K28: =AVERAGE(K4:K27) -> 0.5 | L28: =AVERAGE(L4:L27) -> 1 | M28: =AVERAGE(M4:M27) -> 1 | N28: =AVERAGE(N4:N27) -> 0.73525
A29: Gerente | B29: Vitor | F29: =F33/F32 -> 1 | G29: =G33/G32 -> 0.61 | H29: =H33/H32 -> 0.5 | I29: =I33/I32 -> 1 | J29: =J33/J32 -> 1 | K29: =K33/K32 -> 0 | L29: =L33/L32 -> 0 | M29: =M33/M32 -> 0 | N29: =N33/N32 -> 0.76
F30: =COUNTIF($D4:$D27,$B34) -> 0 | G30: =COUNTIF($D4:$D27,$B34) -> 0 | H30: =COUNTIF($D4:$D27,$B34) -> 0 | I30: =COUNTIF($D4:$D27,$B34) -> 0 | J30: =COUNTIF($D4:$D27,$B34) -> 0 | K30: =COUNTIF($D4:$D27,$B34) -> 0 | L30: =COUNTIF($D4:$D27,$B34) -> 0 | M30: =COUNTIF($D4:$D27,$B34) -> 0 | N30: =COUNTIF($D4:$D27,$B34) -> 0
F31: =SUMIF(D4:D27,B34,F4:F27) -> 0 | G31: =SUMIF($D4:$D27,$B34,G4:G27) -> 0 | H31: =SUMIF($D4:$D27,$B34,H4:H27) -> 0 | I31: =SUMIF($D4:$D27,$B34,I4:I27) -> 0 | J31: =SUMIF($D4:$D27,$B34,J4:J27) -> 0 | K31: =SUMIF($D4:$D27,$B34,K4:K27) -> 0 | L31: =SUMIF($D4:$D27,$B34,L4:L27) -> 0 | M31: =SUMIF($D4:$D27,$B34,M4:M27) -> 0 | N31: =SUMIF($D4:$D27,$B34,N4:N27) -> 0
F32: =COUNTIF($C4:$C27,1) -> 1 | G32: =COUNTIF($C4:$C27,1) -> 1 | H32: =COUNTIF($C4:$C27,1) -> 1 | I32: =COUNTIF($C4:$C27,1) -> 1 | J32: =COUNTIF($C4:$C27,1) -> 1 | K32: =COUNTIF($C4:$C27,1) -> 1 | L32: =COUNTIF($C4:$C27,1) -> 1 | M32: =COUNTIF($C4:$C27,1) -> 1 | N32: =COUNTIF($C4:$C27,1) -> 1
F33: =SUMIF($C4:$C27,1,F4:F27) -> 1 | G33: =SUMIF($C4:$C27,1,G4:G27) -> 0.61 | H33: =SUMIF($C4:$C27,1,H4:H27) -> 0.5 | I33: =SUMIF($C4:$C27,1,I4:I27) -> 1 | J33: =SUMIF($C4:$C27,1,J4:J27) -> 1 | K33: =SUMIF($C4:$C27,1,K4:K27) -> 0 | L33: =SUMIF($C4:$C27,1,L4:L27) -> 0 | M33: =SUMIF($C4:$C27,1,M4:M27) -> 0 | N33: =SUMIF($C4:$C27,1,N4:N27) -> 0.76
A34: Loja | F34: =F31/F30 -> #DIV/0! | G34: =G31/G30 -> #DIV/0! | H34: =H31/H30 -> #DIV/0! | I34: =I31/I30 -> #DIV/0! | J34: =J31/J30 -> #DIV/0! | K34: =K31/K30 -> #DIV/0! | L34: =L31/L30 -> #DIV/0! | M34: =M31/M30 -> #DIV/0! | N34: =N31/N30 -> #DIV/0!
B35: Nota por dep. | F35: =AVERAGE(F4:H27) -> 0.70666667 | I35: =AVERAGE(I4:J27) -> 0.90875 | L35: =AVERAGE(L4:N27) -> 0.8235

Sheet Gestão de Turno
A2: Bruna | J2: Isaac | S2: Isabel
B4: Real | C4: Planificado | D4: Diferença | F4: Real | G4: Planificado | H4: Diferença | K4: Real | L4: Planificado | M4: Diferença | O4: Real | P4: Planificado | Q4: Diferença | T4: Real | U4: Planificado | V4: Diferença | X4: Real | Y4: Planificado | Z4: Diferença
A5: Vendas (16h) | E5: Vendas (16h) | J5: Vendas (16h) | N5: Vendas (16h) | S5: Vendas (16h) | W5: Vendas (16h)
A6: GC's | E6: GC's | J6: GC's | N6: GC's | S6: GC's | W6: GC's
A7: BM | E7: BM | J7: BM | N7: BM | S7: BM | W7: BM
A8: Horas | E8: Horas | J8: Horas | N8: Horas | S8: Horas | W8: Horas
A9: MO | E9: MO | J9: MO | N9: MO | S9: MO | W9: MO
A10: Perdas | E10: Perdas | J10: Perdas | N10: Perdas | S10: Perdas | W10: Perdas
A11: Refeições | E11: Refeições | J11: Refeições | N11: Refeições | S11: Refeições | W11: Refeições
A12: TET | D12: Objetivo 150" | E12: TET | H12: Objetivo 150" | J12: TET | M12: Objetivo 150" | N12: TET | Q12: Objetivo 150" | S12: TET | V12: Objetivo 150" | W12: TET | Z12: Objetivo 150"
A13: Tempo serviço | D13: Objetivo 90" | E13: Tempo serviço | H13: Objetivo 90" | J13: Tempo serviço | M13: Objetivo 90" | N13: Tempo serviço | Q13: Objetivo 90" | S13: Tempo serviço | V13: Objetivo 90" | W13: Tempo serviço | Z13: Objetivo 90"
A14: CMP % | E14: CMP % | J14: CMP % | N14: CMP % | O14: =(((SUMIF([2]Jan!O192,">0")+SUMIF([2]Fev!O192,">0")+SUMIF([2]Mar!O192,">0")+SUMIF([2]Abr!O192,">0")+SUMIF([2]Mai!O192,">0")+SUMIF([2]Jun!O192,">0")+SUMIF([2]Jul!O192,">0")+SUMIF([2]Ago!O192,">0")+SUMIF([2]Set!O192,">0")+SUMIF([2]Out!O192,">0")+SUMIF([2]Nov!O192,">0")+SUMIF([2]Dez!O192,">0"))/((COUNTIF([2]Jan!O192,">0")+COUNTIF([2]Fev!O192,">0")+COUNTIF([2]Mar!O192,">0")+COUNTIF([2]Abr!O192,">0")+COUNTIF([2]Mai!O192,">0")+COUNTIF([2]Jun!O192,">0")+COUNTIF([2]Jul!O192,">0")+COUNTIF([2]Ago!O192,">0")+COUNTIF([2]Set!O192,">0")+COUNTIF([2]Out!O192,">0")+COUNTIF([2]Nov!O192,">0")+COUNTIF([2]Dez!O192,">0"))))*100)/N18 -> #VALUE! | S14: CMP % | W14: CMP %
A15: P. Limpezas % | E15: P. Limpezas % | J15: P. Limpezas % | N15: P. Limpezas % | O15: =(((SUMIF([2]Jan!O193,">0")+SUMIF([2]Fev!O193,">0")+SUMIF([2]Mar!O193,">0")+SUMIF([2]Abr!O193,">0")+SUMIF([2]Mai!O193,">0")+SUMIF([2]Jun!O193,">0")+SUMIF([2]Jul!O193,">0")+SUMIF([2]Ago!O193,">0")+SUMIF([2]Set!O193,">0")+SUMIF([2]Out!O193,">0")+SUMIF([2]Nov!O193,">0")+SUMIF([2]Dez!O193,">0"))/(COUNTIF([2]Jan!O193,">0")+COUNTIF([2]Fev!O193,">0")+COUNTIF([2]Mar!O193,">0")+COUNTIF([2]Abr!O193,">0")+COUNTIF([2]Mai!O193,">0")+COUNTIF([2]Jun!O193,">0")+COUNTIF([2]Jul!O193,">0")+COUNTIF([2]Ago!O193,">0")+COUNTIF([2]Set!O193,">0")+COUNTIF([2]Out!O193,">0")+COUNTIF([2]Nov!O193,">0")+COUNTIF([2]Dez!O193,">0"))*100)/N18) -> #VALUE! | S15: P. Limpezas % | W15: P. Limpezas %
A16: Reembolsos | B16: Quantidade | C16: Valor | D16: Média | E16: Reembolsos | F16: Quantidade | G16: Valor | H16: Média | J16: Reembolsos | K16: Quantidade | L16: Valor | M16: Média | N16: Reembolsos | O16: Quantidade | P16: Valor | Q16: Média | S16: Reembolsos | T16: Quantidade | U16: Valor | V16: Média | W16: Reembolsos | X16: Quantidade | Y16: Valor | Z16: Média
Q17: =P17/O17 -> #DIV/0!
A19: Janice | B19: , | J19: Luis | S19: Uilson
B21: Real | C21: Planificado | D21: Diferença | F21: Real | G21: Planificado | H21: Diferença | K21: Real | L21: Planificado | M21: Diferença | O21: Real | P21: Planificado | Q21: Diferença | T21: Real | U21: Planificado | V21: Diferença | X21: Real | Y21: Planificado | Z21: Diferença
A22: Vendas (16h) | E22: Vendas (16h) | J22: Vendas (16h) | N22: Vendas (16h) | S22: Vendas (16h) | W22: Vendas (16h)
A23: GC's | E23: GC's | J23: GC's | N23: GC's | S23: GC's | W23: GC's
A24: BM | E24: BM | J24: BM | N24: BM | S24: BM | W24: BM
A25: Horas | E25: Horas | J25: Horas | N25: Horas | S25: Horas | W25: Horas
A26: MO | E26: MO | J26: MO | N26: MO | S26: MO | W26: MO
A27: Perdas | E27: Perdas | J27: Perdas | N27: Perdas | S27: Perdas | W27: Perdas
A28: Refeições | E28: Refeições | J28: Refeições | N28: Refeições | S28: Refeições | W28: Refeições
A29: TET | D29: Objetivo 150" | E29: TET | H29: Objetivo 150" | J29: TET | M29: Objetivo 150" | N29: TET | Q29: Objetivo 150" | S29: TET | V29: Objetivo 150" | W29: TET | Z29: Objetivo 150"
A30: Tempo serviço | D30: Objetivo 90" | E30: Tempo serviço | H30: Objetivo 90" | J30: Tempo serviço | M30: Objetivo 90" | N30: Tempo serviço | Q30: Objetivo 90" | S30: Tempo serviço | V30: Objetivo 90" | W30: Tempo serviço | Z30: Objetivo 90"
A31: CMP % | E31: CMP % | F31: =(((SUMIF([2]Jan!F209,">0")+SUMIF([2]Fev!F209,">0")+SUMIF([2]Mar!F209,">0")+SUMIF([2]Abr!F209,">0")+SUMIF([2]Mai!F209,">0")+SUMIF([2]Jun!F209,">0")+SUMIF([2]Jul!F209,">0")+SUMIF([2]Ago!F209,">0")+SUMIF([2]Set!F209,">0")+SUMIF([2]Out!F209,">0")+SUMIF([2]Nov!F209,">0")+SUMIF([2]Dez!F209,">0"))/((COUNTIF([2]Jan!F209,">0")+COUNTIF([2]Fev!F209,">0")+COUNTIF([2]Mar!F209,">0")+COUNTIF([2]Abr!F209,">0")+COUNTIF([2]Mai!F209,">0")+COUNTIF([2]Jun!F209,">0")+COUNTIF([2]Jul!F209,">0")+COUNTIF([2]Ago!F209,">0")+COUNTIF([2]Set!F209,">0")+COUNTIF([2]Out!F209,">0")+COUNTIF([2]Nov!F209,">0")+COUNTIF([2]Dez!F209,">0"))))*100)/E35 -> #VALUE! | J31: CMP % | N31: CMP % | S31: CMP % | W31: CMP %
A32: P. Limpezas % | E32: P. Limpezas % | F32: =(((SUMIF([2]Jan!F210,">0")+SUMIF([2]Fev!F210,">0")+SUMIF([2]Mar!F210,">0")+SUMIF([2]Abr!F210,">0")+SUMIF([2]Mai!F210,">0")+SUMIF([2]Jun!F210,">0")+SUMIF([2]Jul!F210,">0")+SUMIF([2]Ago!F210,">0")+SUMIF([2]Set!F210,">0")+SUMIF([2]Out!F210,">0")+SUMIF([2]Nov!F210,">0")+SUMIF([2]Dez!F210,">0"))/(COUNTIF([2]Jan!F210,">0")+COUNTIF([2]Fev!F210,">0")+COUNTIF([2]Mar!F210,">0")+COUNTIF([2]Abr!F210,">0")+COUNTIF([2]Mai!F210,">0")+COUNTIF([2]Jun!F210,">0")+COUNTIF([2]Jul!F210,">0")+COUNTIF([2]Ago!F210,">0")+COUNTIF([2]Set!F210,">0")+COUNTIF([2]Out!F210,">0")+COUNTIF([2]Nov!F210,">0")+COUNTIF([2]Dez!F210,">0"))*100)/E35) -> #VALUE! | J32: P. Limpezas % | N32: P. Limpezas % | S32: P. Limpezas % | W32: P. Limpezas %
A33: Reembolsos | B33: Quantidade | C33: Valor | D33: Média | E33: Reembolsos | F33: Quantidade | G33: Valor | H33: Média | J33: Reembolsos | K33: Quantidade | L33: Valor | M33: Média | N33: Reembolsos | O33: Quantidade | P33: Valor | Q33: Média | S33: Reembolsos | T33: Quantidade | U33: Valor | V33: Média | W33: Reembolsos | X33: Quantidade | Y33: Valor | Z33: Média
A36: Claudia | J36: Hugo | S36: Marília
B38: Real | C38: Planificado | D38: Diferença | F38: Real | G38: Planificado | H38: Diferença | K38: Real | L38: Planificado | M38: Diferença | O38: Real | P38: Planificado | Q38: Diferença
A39: Vendas (16h) | E39: Vendas (16h) | J39: Vendas (16h) | N39: Vendas (16h) | Q39: =O39-P39 -> 0 | S39: Vendas (16h) | W39: Vendas (16h)
A40: GC's | E40: GC's | J40: GC's | N40: GC's | Q40: =O40-P40 -> 0 | S40: GC's | W40: GC's
A41: BM | E41: BM | J41: BM | N41: BM | Q41: =O41-P41 -> 0 | S41: BM | W41: BM
A42: Horas | E42: Horas | J42: Horas | N42: Horas | Q42: =O42-P42 -> 0 | S42: Horas | W42: Horas
A43: MO | E43: MO | J43: MO | N43: MO | Q43: =O43-P43 -> 0 | S43: MO | W43: MO
A44: Perdas | E44: Perdas | J44: Perdas | N44: Perdas | Q44: =O44-P44 -> 0 | S44: Perdas | W44: Perdas
A45: Refeições | E45: Refeições | J45: Refeições | N45: Refeições | Q45: =O45-P45 -> 0 | S45: Refeições | W45: Refeições
A46: TET | D46: Objetivo 150" | E46: TET | H46: Objetivo 150" | J46: TET | M46: Objetivo 150" | N46: TET | Q46: Objetivo 150" | S46: TET | V46: Objetivo 150" | W46: TET | Z46: Objetivo 150"
A47: Tempo serviço | D47: Objetivo 90" | E47: Tempo serviço | H47: Objetivo 90" | J47: Tempo serviço | M47: Objetivo 90" | N47: Tempo serviço | Q47: Objetivo 90" | S47: Tempo serviço | V47: Objetivo 90" | W47: Tempo serviço | Z47: Objetivo 90"
...

Sheet Gerentes
C2: BSV | D2: VSC | E2: Vendas | F2: ∆Vendas | G2: Horas | H2: Produtividade | I2: Mão obra | J2: Perdas | K2: TET | L2: R2P | M2: Reembolsos | N2: µ Reembolsos
B3: Bruna | C3: =BSV!P4 -> #DIV/0! | D3: =VSC!$D$36 -> 0 | E3: ='Gestão de Turno'!B5+'Gestão de Turno'!F5 -> 0 | F3: ='Gestão de Turno'!D5+'Gestão de Turno'!H5 -> 0 | G3: ='Gestão de Turno'!B8+'Gestão de Turno'!F8 -> 0 | H3: =E3/G3 -> #DIV/0! | I3: =(G3*6.7)/E3 -> #DIV/0! | J3: =('Gestão de Turno'!B10+'Gestão de Turno'!F10)/E3 -> #DIV/0! | K3: =R3 -> 0 | L3: =T3 -> 0 | M3: ='Gestão de Turno'!B17 -> 0 | N3: =('Gestão de Turno'!C17+'Gestão de Turno'!G17)/('Gestão de Turno'!B17+'Gestão de Turno'!F17) -> #DIV/0! | R3: {=('Gestão de Turno'!B12:C12+'Gestão de Turno'!F12:G12)/2} -> 0 | S3: 0 | T3: {=('Gestão de Turno'!B13:C13+'Gestão de Turno'!F13:G13)/2} -> 0 | U3: 0
B4: Isaac | C4: =BSV!P5 -> #DIV/0! | D4: =VSC!$D$36 -> 0 | E4: ='Gestão de Turno'!K5+'Gestão de Turno'!O5 -> 0 | F4: ='Gestão de Turno'!M5+'Gestão de Turno'!Q5 -> 0 | G4: ='Gestão de Turno'!K8+'Gestão de Turno'!O8 -> 0 | H4: =E4/G4 -> #DIV/0! | I4: =(G4*6.7)/E4 -> #DIV/0! | J4: =('Gestão de Turno'!K10+'Gestão de Turno'!O10)/E4 -> #DIV/0! | K4: =R4 -> 0 | L4: =T4 -> 0 | M4: ='Gestão de Turno'!K17 -> 0 | N4: =('Gestão de Turno'!L17+'Gestão de Turno'!O17)/('Gestão de Turno'!K17+'Gestão de Turno'!O17) -> #DIV/0! | R4: {=('Gestão de Turno'!K12:L12+'Gestão de Turno'!O12:P12)/2} -> 0 | S4: 0 | T4: {=('Gestão de Turno'!K13:L13+'Gestão de Turno'!O13:P13)/2} -> 0 | U4: 0
B5: Isabel | C5: =BSV!P6 -> #DIV/0! | D5: =VSC!$D$36 -> 0 | E5: ='Gestão de Turno'!T5+'Gestão de Turno'!X5 -> 0 | F5: ='Gestão de Turno'!V5+'Gestão de Turno'!Z5 -> 0 | G5: ='Gestão de Turno'!T8+'Gestão de Turno'!X8 -> 0 | H5: =E5/G5 -> #DIV/0! | I5: =(G5*6.7)/E5 -> #DIV/0! | J5: =('Gestão de Turno'!T10+'Gestão de Turno'!X10)/E5 -> #DIV/0! | K5: =R5 -> 0 | L5: =T5 -> 0 | M5: ='Gestão de Turno'!T17+'Gestão de Turno'!X17 -> 0 | N5: =('Gestão de Turno'!U17+'Gestão de Turno'!Y17)/('Gestão de Turno'!T17+'Gestão de Turno'!X17) -> #DIV/0! | R5: {=('Gestão de Turno'!T12:U12+'Gestão de Turno'!X12:Y12)/2} -> 0 | S5: 0 | T5: {=('Gestão de Turno'!T13:U13+'Gestão de Turno'!X13:Y13)/2} -> 0 | U5: 0
B6: Janice | C6: =BSV!P7 -> #DIV/0! | D6: =VSC!$D$36 -> 0 | E6: ='Gestão de Turno'!B22+'Gestão de Turno'!F22 -> 0 | F6: ='Gestão de Turno'!D22+'Gestão de Turno'!H22 -> 0 | G6: ='Gestão de Turno'!B25+'Gestão de Turno'!F25 -> 0 | H6: =E6/G6 -> #DIV/0! | I6: =(G6*6.7)/E6 -> #DIV/0! | J6: =('Gestão de Turno'!B27+'Gestão de Turno'!F27)/E6 -> #DIV/0! | K6: =R6 -> 0 | L6: =T6 -> 0 | M6: ='Gestão de Turno'!B34+'Gestão de Turno'!F34 -> 0 | N6: =('Gestão de Turno'!C34+'Gestão de Turno'!G34)/('Gestão de Turno'!F34+'Gestão de Turno'!B34) -> #DIV/0! | R6: {=('Gestão de Turno'!B29:C29+'Gestão de Turno'!F29:G29)/2} -> 0 | S6: 0 | T6: {=('Gestão de Turno'!B30:C30+'Gestão de Turno'!F30:G30)/2} -> 0 | U6: 0
C7: =BSV!P9 -> 0.7855 | D7: =VSC!$D$36 -> 0 | E7: ='Gestão de Turno'!K22+'Gestão de Turno'!O22 -> 0 | F7: ='Gestão de Turno'!M22+'Gestão de Turno'!Q22 -> 0 | G7: ='Gestão de Turno'!K25+'Gestão de Turno'!O25 -> 0 | H7: =E7/G7 -> #DIV/0! | I7: =(G7*6.7)/E7 -> #DIV/0! | J7: =('Gestão de Turno'!K27+'Gestão de Turno'!O27)/E7 -> #DIV/0! | K7: =R7 -> 0 | L7: =T7 -> 0 | M7: ='Gestão de Turno'!K34+'Gestão de Turno'!O34 -> 0 | N7: =('Gestão de Turno'!L34+'Gestão de Turno'!P34)/('Gestão de Turno'!K34+'Gestão de Turno'!O34) -> #DIV/0! | R7: {=('Gestão de Turno'!K29:L29+'Gestão de Turno'!O29:P29)/2} -> 0 | S7: 0 | T7: {=('Gestão de Turno'!K30:L30+'Gestão de Turno'!O30:P30)/2} -> 0 | U7: 0
